Workbook

Sheet README
A1: UK Fuel Price Outlook 2026 to 2036
A2: Petrol and diesel pump prices: statistical baseline and sourced scenarios
A3: Prepared by Abdul Mohi Choudhry | Version 1.0, 7 October 2026 | Price data to 28 September 2026 | Tools: R and Excel
A4: PURPOSE
A5: What this is | B5: A 10-year look at where UK petrol and diesel pump prices could go. It combines a statistical baseline (an ARIMA time-series model built in R) with three transparent scenarios built in Excel from published oil price, inflation and fuel duty assumptions. It is an analytical exercise: the results are conditional projections, not predictions, and not financial advice.
A7: KEY FINDINGS (default assumptions, pence per litre, September 2036)
A8: Petrol | B8: Today (Sep-26 average) 169.5p. Statistical baseline 169.1p (80% range 91p to 247p). Scenarios: Low 167p, Central 214p, High 238p.
A9: Diesel | B9: Today (Sep-26 average) 192.5p. Statistical baseline 176.3p (80% range 110p to 242p). Scenarios: Low 195p, Central 242p, High 266p.
A10: Prices are at a spike | B10: Diesel rose from about 142p in February 2026 to about 198p by 28 September 2026, and petrol from about 132p to about 173p, following an oil price shock linked to the 2026 Middle East conflict.
A11: Model accuracy | B11: In normal conditions the ARIMA model beat a "no change" benchmark by about a quarter (backtest Jan-24 to Feb-26, RMSE: petrol 5.3p vs 7.1p, diesel 6.2p vs 8.1p). Including the 2026 spike it did no better than the benchmark (petrol 9.8p vs 9.6p, diesel 16.0p vs 15.6p). Past prices alone cannot anticipate shocks.
A12: Why scenarios | B12: The statistical range for 2036 is very wide, so assumptions matter more than the model. The Central scenarios imply roughly +26% for petrol and +25% for diesel by 2036, driven mainly by general inflation and fuel duty returning to its pre-2022 level and then rising with RPI.
A14: HOW TO USE THIS WORKBOOK
A15: Switch fuel | B15: On the Scenarios sheet, choose Petrol or Diesel in cell B3. The starting price, summary table, scenarios and chart all update.
A16: Change assumptions | B16: Sourced inputs are on the Assumptions sheet (blue cells). The Low scenario duty inputs on Scenarios (C12:C13, yellow) can also be changed.
A17: Data check | B17: Cell M2 on Forecast_Data should read "OK". It warns if the diesel forecast columns are incomplete or repeated.
A19: SHEET GUIDE
A20: Weekly_Data | B20: Official weekly UK average pump prices (petrol and diesel, p/litre) from 1 Jan 2018 to 28 Sep 2026, with fuel duty, VAT, diesel premium and tax share of the price.
A21: Monthly | B21: Monthly averages of the weekly prices (105 months). This is the series used for the R forecasts.
A22: Annual | B22: Calendar-year averages and year-on-year change. 2026 is year-to-date.
A23: Forecast_Data | B23: 120-month statistical forecast (Oct-26 to Sep-36) for petrol and diesel from R, with 80% and 95% ranges.
A24: Scenarios | B24: Low, Central and High pump-price scenarios against the statistical baseline, with a summary table and chart. Choose the fuel in B3.
A25: Assumptions | B25: Every scenario input with its source, including the DESNZ oil price table.
A26: Scenario_Calc | B26: Month-by-month workings behind the scenarios (formulas only).
A27: Charts | B27: Weekly, monthly and annual price charts, plus the R forecast charts for petrol and diesel.
A29: METHOD
A30: Data preparation | B30: Weekly Monday prices averaged to calendar months (Jan-18 to Sep-26, 105 months).
A31: Statistical baseline | B31: ARIMA models fitted automatically in R (forecast package): petrol ARIMA(2,1,2) with no drift; diesel ARIMA(2,1,2)(0,0,1)[12], which adds a seasonal moving-average term. Each forecasts 120 months with 80% and 95% ranges.
A32: Backtest | B32: Models trained on Jan-18 to Dec-23 and tested from Jan-24 against a "no change" (naive) benchmark. ETS was also tested and performed poorly, so it is not used.
A33: Scenarios | B33: Pump price = (crude oil cost + other costs + fuel duty) x (1 + VAT). Crude cost = Brent x 100 / (litres per barrel x GBP/USD). Brent moves from today's level to the DESNZ low, central or high path over one year. Other costs (refining, distribution, retail margin) grow with inflation. Fuel duty follows the stated policy in Central and High, and is frozen in Low.
A35: DATA SOURCES
A36: Pump prices | B36: DESNZ, Weekly road fuel prices (GOV.UK).
A37: Oil price scenarios | B37: DESNZ, Fossil Fuel Price Assumptions 2025 (GOV.UK, January 2026): low, central and high Brent paths in real 2024 prices.
A38: Current oil price | B38: US EIA, Short-Term Energy Outlook, September 2026: Brent averaged $91 a barrel in August 2026 (eia.gov).
A39: Inflation | B39: Office for Budget Responsibility, Economic and fiscal outlook, March 2026: CPI 2.0% from 2027, RPI about 2.9% a year in 2027 to 2029 and 2.4% long run (obr.uk).
A40: Fuel duty | B40: HMRC and HM Treasury, Amended Fuel Duty rates for 2026 to 2027 (GOV.UK, 22 May 2026): 5p cut extended to 31 December 2026.
A41: Exchange rate | B41: Pound Sterling Live: USD/GBP 2026 average 0.7441, about 1.34 GBP/USD, held constant.
A43: ASSUMPTIONS AND LIMITATIONS
A44: 1. Not forecasts | B44: The scenarios are conditional projections. DESNZ describes its oil prices as assumptions for stress-testing, and its short-term values were set before the 2026 Middle East conflict.
A45: 2. Fuel duty | B45: Assumes the 5p cut ends on 1 January 2027 with no staging, then RPI uprating from April 2027. The Budget and OBR forecast due on 28 October 2026 may change this. The Low scenario freezes duty at 52.95p, which is the author's assumption and not an official forecast.
A46: 3. Fixed inputs | B46: GBP/USD is held at 1.34, CPI is 2.0% from 2027, and Brent converges to the DESNZ path over one year (a judgement based on the EIA outlook).
...

Sheet Weekly_Data
A1: Week commencing | B1: Petrol (ULSP) pump price (p/litre) | C1: Diesel (ULSD) pump price (p/litre) | D1: Fuel duty (p/litre, both fuels) | E1: VAT rate (%) | F1: Diesel premium over petrol (p/litre) | G1: Tax share of petrol price (duty + VAT) | H1: Tax share of diesel price (duty + VAT)
A2: 43101 | B2: 120.19 | C2: 123.51 | D2: 57.95 | E2: 20 | F2: =C2-B2 -> 3.32 | G2: =(B2-B2/(1+E2/100)+D2)/B2 -> 0.64881992 | H2: =(C2-C2/(1+E2/100)+D2)/C2 -> 0.63585944
A3: 43108 | B3: 120.52 | C3: 123.97 | D3: 57.95 | E3: 20 | F3: =C3-B3 -> 3.45 | G3: =(B3-B3/(1+E3/100)+D3)/B3 -> 0.64749972 | H3: =(C3-C3/(1+E3/100)+D3)/C3 -> 0.63411847
A4: 43115 | B4: 120.96 | C4: 124.58 | D4: 57.95 | E4: 20 | F4: =C4-B4 -> 3.62 | G4: =(B4-B4/(1+E4/100)+D4)/B4 -> 0.64575066 | H4: =(C4-C4/(1+E4/100)+D4)/C4 -> 0.63182961
A5: 43122 | B5: 121.5 | C5: 125.07 | D5: 57.95 | E5: 20 | F5: =C5-B5 -> 3.57 | G5: =(B5-B5/(1+E5/100)+D5)/B5 -> 0.6436214 | H5: =(C5-C5/(1+E5/100)+D5)/C5 -> 0.6300072
A6: 43129 | B6: 121.69 | C6: 125.32 | D6: 57.95 | E6: 20 | F6: =C6-B6 -> 3.63 | G6: =(B6-B6/(1+E6/100)+D6)/B6 -> 0.64287671 | H6: =(C6-C6/(1+E6/100)+D6)/C6 -> 0.62908288
A7: 43136 | B7: 121.73 | C7: 125.36 | D7: 57.95 | E7: 20 | F7: =C7-B7 -> 3.63 | G7: =(B7-B7/(1+E7/100)+D7)/B7 -> 0.64272023 | H7: =(C7-C7/(1+E7/100)+D7)/C7 -> 0.62893533
A8: 43143 | B8: 121.58 | C8: 125.02 | D8: 57.95 | E8: 20 | F8: =C8-B8 -> 3.44 | G8: =(B8-B8/(1+E8/100)+D8)/B8 -> 0.64330756 | H8: =(C8-C8/(1+E8/100)+D8)/C8 -> 0.6301925
A9: 43150 | B9: 120.52 | C9: 124.18 | D9: 57.95 | E9: 20 | F9: =C9-B9 -> 3.66 | G9: =(B9-B9/(1+E9/100)+D9)/B9 -> 0.64749972 | H9: =(C9-C9/(1+E9/100)+D9)/C9 -> 0.63332796
A10: 43157 | B10: 119.55 | C10: 123.09 | D10: 57.95 | E10: 20 | F10: =C10-B10 -> 3.54 | G10: =(B10-B10/(1+E10/100)+D10)/B10 -> 0.65140109 | H10: =(C10-C10/(1+E10/100)+D10)/C10 -> 0.63746039
A11: 43164 | B11: 119.29 | C11: 122.92 | D11: 57.95 | E11: 20 | F11: =C11-B11 -> 3.63 | G11: =(B11-B11/(1+E11/100)+D11)/B11 -> 0.6524576 | H11: =(C11-C11/(1+E11/100)+D11)/C11 -> 0.63811151
A12: 43171 | B12: 119.11 | C12: 122.96 | D12: 57.95 | E12: 20 | F12: =C12-B12 -> 3.85 | G12: =(B12-B12/(1+E12/100)+D12)/B12 -> 0.65319173 | H12: =(C12-C12/(1+E12/100)+D12)/C12 -> 0.63795814
A13: 43178 | B13: 119.17 | C13: 122.84 | D13: 57.95 | E13: 20 | F13: =C13-B13 -> 3.67 | G13: =(B13-B13/(1+E13/100)+D13)/B13 -> 0.65294677 | H13: =(C13-C13/(1+E13/100)+D13)/C13 -> 0.63841854
... A458: 46293 | B458: 173.46 | C458: 197.58 | D458: 52.95 | E458: 20 | F458: =C458-B458 -> 24.12 | G458: =(B458-B458/(1+E458/100)+D458)/B458 -> 0.47192436 | H458: =(C458-C458/(1+E458/100)+D458)/C458 -> 0.43465938
A460: Source: DESNZ weekly road fuel prices (GOV.UK), CSV updated 29 Sep 2026. Duty/VAT per the official CSV.

Sheet Monthly
A1: Month | B1: Avg petrol (p/litre) | C1: Avg diesel (p/litre) | D1: Weeks in month (count) | E1: Diesel premium (p/litre)
A2: 43101 | B2: =AVERAGEIFS(Weekly_Data!$B$2:$B$458,Weekly_Data!$A$2:$A$458,">="&$A2,Weekly_Data!$A$2:$A$458,"<"&EDATE($A2,1)) -> 120.972 | C2: =AVERAGEIFS(Weekly_Data!$C$2:$C$458,Weekly_Data!$A$2:$A$458,">="&$A2,Weekly_Data!$A$2:$A$458,"<"&EDATE($A2,1)) -> 124.49 | D2: =COUNTIFS(Weekly_Data!$A$2:$A$458,">="&$A2,Weekly_Data!$A$2:$A$458,"<"&EDATE($A2,1)) -> 5 | E2: =C2-B2 -> 3.518
A3: 43132 | B3: =AVERAGEIFS(Weekly_Data!$B$2:$B$458,Weekly_Data!$A$2:$A$458,">="&$A3,Weekly_Data!$A$2:$A$458,"<"&EDATE($A3,1)) -> 120.845 | C3: =AVERAGEIFS(Weekly_Data!$C$2:$C$458,Weekly_Data!$A$2:$A$458,">="&$A3,Weekly_Data!$A$2:$A$458,"<"&EDATE($A3,1)) -> 124.4125 | D3: =COUNTIFS(Weekly_Data!$A$2:$A$458,">="&$A3,Weekly_Data!$A$2:$A$458,"<"&EDATE($A3,1)) -> 4 | E3: =C3-B3 -> 3.5675
A4: 43160 | B4: =AVERAGEIFS(Weekly_Data!$B$2:$B$458,Weekly_Data!$A$2:$A$458,">="&$A4,Weekly_Data!$A$2:$A$458,"<"&EDATE($A4,1)) -> 119.2 | C4: =AVERAGEIFS(Weekly_Data!$C$2:$C$458,Weekly_Data!$A$2:$A$458,">="&$A4,Weekly_Data!$A$2:$A$458,"<"&EDATE($A4,1)) -> 122.905 | D4: =COUNTIFS(Weekly_Data!$A$2:$A$458,">="&$A4,Weekly_Data!$A$2:$A$458,"<"&EDATE($A4,1)) -> 4 | E4: =C4-B4 -> 3.705
A5: 43191 | B5: =AVERAGEIFS(Weekly_Data!$B$2:$B$458,Weekly_Data!$A$2:$A$458,">="&$A5,Weekly_Data!$A$2:$A$458,"<"&EDATE($A5,1)) -> 120.722 | C5: =AVERAGEIFS(Weekly_Data!$C$2:$C$458,Weekly_Data!$A$2:$A$458,">="&$A5,Weekly_Data!$A$2:$A$458,"<"&EDATE($A5,1)) -> 124.464 | D5: =COUNTIFS(Weekly_Data!$A$2:$A$458,">="&$A5,Weekly_Data!$A$2:$A$458,"<"&EDATE($A5,1)) -> 5 | E5: =C5-B5 -> 3.742
A6: 43221 | B6: =AVERAGEIFS(Weekly_Data!$B$2:$B$458,Weekly_Data!$A$2:$A$458,">="&$A6,Weekly_Data!$A$2:$A$458,"<"&EDATE($A6,1)) -> 125.275 | C6: =AVERAGEIFS(Weekly_Data!$C$2:$C$458,Weekly_Data!$A$2:$A$458,">="&$A6,Weekly_Data!$A$2:$A$458,"<"&EDATE($A6,1)) -> 129.2425 | D6: =COUNTIFS(Weekly_Data!$A$2:$A$458,">="&$A6,Weekly_Data!$A$2:$A$458,"<"&EDATE($A6,1)) -> 4 | E6: =C6-B6 -> 3.9675
A7: 43252 | B7: =AVERAGEIFS(Weekly_Data!$B$2:$B$458,Weekly_Data!$A$2:$A$458,">="&$A7,Weekly_Data!$A$2:$A$458,"<"&EDATE($A7,1)) -> 128.035 | C7: =AVERAGEIFS(Weekly_Data!$C$2:$C$458,Weekly_Data!$A$2:$A$458,">="&$A7,Weekly_Data!$A$2:$A$458,"<"&EDATE($A7,1)) -> 132.0525 | D7: =COUNTIFS(Weekly_Data!$A$2:$A$458,">="&$A7,Weekly_Data!$A$2:$A$458,"<"&EDATE($A7,1)) -> 4 | E7: =C7-B7 -> 4.0175
A8: 43282 | B8: =AVERAGEIFS(Weekly_Data!$B$2:$B$458,Weekly_Data!$A$2:$A$458,">="&$A8,Weekly_Data!$A$2:$A$458,"<"&EDATE($A8,1)) -> 127.204 | C8: =AVERAGEIFS(Weekly_Data!$C$2:$C$458,Weekly_Data!$A$2:$A$458,">="&$A8,Weekly_Data!$A$2:$A$458,"<"&EDATE($A8,1)) -> 131.61 | D8: =COUNTIFS(Weekly_Data!$A$2:$A$458,">="&$A8,Weekly_Data!$A$2:$A$458,"<"&EDATE($A8,1)) -> 5 | E8: =C8-B8 -> 4.406
A9: 43313 | B9: =AVERAGEIFS(Weekly_Data!$B$2:$B$458,Weekly_Data!$A$2:$A$458,">="&$A9,Weekly_Data!$A$2:$A$458,"<"&EDATE($A9,1)) -> 128.595 | C9: =AVERAGEIFS(Weekly_Data!$C$2:$C$458,Weekly_Data!$A$2:$A$458,">="&$A9,Weekly_Data!$A$2:$A$458,"<"&EDATE($A9,1)) -> 132.78 | D9: =COUNTIFS(Weekly_Data!$A$2:$A$458,">="&$A9,Weekly_Data!$A$2:$A$458,"<"&EDATE($A9,1)) -> 4 | E9: =C9-B9 -> 4.185
A10: 43344 | B10: =AVERAGEIFS(Weekly_Data!$B$2:$B$458,Weekly_Data!$A$2:$A$458,">="&$A10,Weekly_Data!$A$2:$A$458,"<"&EDATE($A10,1)) -> 130.295 | C10: =AVERAGEIFS(Weekly_Data!$C$2:$C$458,Weekly_Data!$A$2:$A$458,">="&$A10,Weekly_Data!$A$2:$A$458,"<"&EDATE($A10,1)) -> 134.33 | D10: =COUNTIFS(Weekly_Data!$A$2:$A$458,">="&$A10,Weekly_Data!$A$2:$A$458,"<"&EDATE($A10,1)) -> 4 | E10: =C10-B10 -> 4.035
A11: 43374 | B11: =AVERAGEIFS(Weekly_Data!$B$2:$B$458,Weekly_Data!$A$2:$A$458,">="&$A11,Weekly_Data!$A$2:$A$458,"<"&EDATE($A11,1)) -> 130.512 | C11: =AVERAGEIFS(Weekly_Data!$C$2:$C$458,Weekly_Data!$A$2:$A$458,">="&$A11,Weekly_Data!$A$2:$A$458,"<"&EDATE($A11,1)) -> 136.188 | D11: =COUNTIFS(Weekly_Data!$A$2:$A$458,">="&$A11,Weekly_Data!$A$2:$A$458,"<"&EDATE($A11,1)) -> 5 | E11: =C11-B11 -> 5.676
A12: 43405 | B12: =AVERAGEIFS(Weekly_Data!$B$2:$B$458,Weekly_Data!$A$2:$A$458,">="&$A12,Weekly_Data!$A$2:$A$458,"<"&EDATE($A12,1)) -> 128.055 | C12: =AVERAGEIFS(Weekly_Data!$C$2:$C$458,Weekly_Data!$A$2:$A$458,">="&$A12,Weekly_Data!$A$2:$A$458,"<"&EDATE($A12,1)) -> 136.48 | D12: =COUNTIFS(Weekly_Data!$A$2:$A$458,">="&$A12,Weekly_Data!$A$2:$A$458,"<"&EDATE($A12,1)) -> 4 | E12: =C12-B12 -> 8.425
A13: 43435 | B13: =AVERAGEIFS(Weekly_Data!$B$2:$B$458,Weekly_Data!$A$2:$A$458,">="&$A13,Weekly_Data!$A$2:$A$458,"<"&EDATE($A13,1)) -> 121.696 | C13: =AVERAGEIFS(Weekly_Data!$C$2:$C$458,Weekly_Data!$A$2:$A$458,">="&$A13,Weekly_Data!$A$2:$A$458,"<"&EDATE($A13,1)) -> 131.862 | D13: =COUNTIFS(Weekly_Data!$A$2:$A$458,">="&$A13,Weekly_Data!$A$2:$A$458,"<"&EDATE($A13,1)) -> 5 | E13: =C13-B13 -> 10.166
... A106: 46266 | B106: =AVERAGEIFS(Weekly_Data!$B$2:$B$458,Weekly_Data!$A$2:$A$458,">="&$A106,Weekly_Data!$A$2:$A$458,"<"&EDATE($A106,1)) -> 169.5025 | C106: =AVERAGEIFS(Weekly_Data!$C$2:$C$458,Weekly_Data!$A$2:$A$458,">="&$A106,Weekly_Data!$A$2:$A$458,"<"&EDATE($A106,1)) -> 192.5475 | D106: =COUNTIFS(Weekly_Data!$A$2:$A$458,">="&$A106,Weekly_Data!$A$2:$A$458,"<"&EDATE($A106,1)) -> 4 | E106: =C106-B106 -> 23.045
A108: Monthly average of the weekly (Monday) prices that fall in each month. Sep-26 covers weeks to 28 Sep only.

Sheet Annual
A1: Year | B1: Avg petrol (p/litre) | C1: Avg diesel (p/litre) | D1: Petrol YoY change | E1: Diesel YoY change | F1: Avg diesel premium (p/litre) | G1: Weeks of data (count)
A2: 2018 | B2: =AVERAGEIFS(Weekly_Data!$B$2:$B$458,Weekly_Data!$A$2:$A$458,">="&DATE(2018,1,1),Weekly_Data!$A$2:$A$458,"<"&DATE(2019,1,1)) -> 125.03264 | C2: =AVERAGEIFS(Weekly_Data!$C$2:$C$458,Weekly_Data!$A$2:$A$458,">="&DATE(2018,1,1),Weekly_Data!$A$2:$A$458,"<"&DATE(2019,1,1)) -> 130.03547 | F2: =C2-B2 -> 5.0028302 | G2: =COUNTIFS(Weekly_Data!$A$2:$A$458,">="&DATE(2018,1,1),Weekly_Data!$A$2:$A$458,"<"&DATE(2019,1,1)) -> 53
A3: 2019 | B3: =AVERAGEIFS(Weekly_Data!$B$2:$B$458,Weekly_Data!$A$2:$A$458,">="&DATE(2019,1,1),Weekly_Data!$A$2:$A$458,"<"&DATE(2020,1,1)) -> 124.97058 | C3: =AVERAGEIFS(Weekly_Data!$C$2:$C$458,Weekly_Data!$A$2:$A$458,">="&DATE(2019,1,1),Weekly_Data!$A$2:$A$458,"<"&DATE(2020,1,1)) -> 131.70692 | D3: =B3/B2-1 -> -0.00049638707 | E3: =C3/C2-1 -> 0.012853811 | F3: =C3-B3 -> 6.7363462 | G3: =COUNTIFS(Weekly_Data!$A$2:$A$458,">="&DATE(2019,1,1),Weekly_Data!$A$2:$A$458,"<"&DATE(2020,1,1)) -> 52
A4: 2020 | B4: =AVERAGEIFS(Weekly_Data!$B$2:$B$458,Weekly_Data!$A$2:$A$458,">="&DATE(2020,1,1),Weekly_Data!$A$2:$A$458,"<"&DATE(2021,1,1)) -> 114.09269 | C4: =AVERAGEIFS(Weekly_Data!$C$2:$C$458,Weekly_Data!$A$2:$A$458,">="&DATE(2020,1,1),Weekly_Data!$A$2:$A$458,"<"&DATE(2021,1,1)) -> 119.45558 | D4: =B4/B3-1 -> -0.087043566 | E4: =C4/C3-1 -> -0.093019758 | F4: =C4-B4 -> 5.3628846 | G4: =COUNTIFS(Weekly_Data!$A$2:$A$458,">="&DATE(2020,1,1),Weekly_Data!$A$2:$A$458,"<"&DATE(2021,1,1)) -> 52
A5: 2021 | B5: =AVERAGEIFS(Weekly_Data!$B$2:$B$458,Weekly_Data!$A$2:$A$458,">="&DATE(2021,1,1),Weekly_Data!$A$2:$A$458,"<"&DATE(2022,1,1)) -> 131.39788 | C5: =AVERAGEIFS(Weekly_Data!$C$2:$C$458,Weekly_Data!$A$2:$A$458,">="&DATE(2021,1,1),Weekly_Data!$A$2:$A$458,"<"&DATE(2022,1,1)) -> 135.03788 | D5: =B5/B4-1 -> 0.15167661 | E5: =C5/C4-1 -> 0.13044437 | F5: =C5-B5 -> 3.64 | G5: =COUNTIFS(Weekly_Data!$A$2:$A$458,">="&DATE(2021,1,1),Weekly_Data!$A$2:$A$458,"<"&DATE(2022,1,1)) -> 52
A6: 2022 | B6: =AVERAGEIFS(Weekly_Data!$B$2:$B$458,Weekly_Data!$A$2:$A$458,">="&DATE(2022,1,1),Weekly_Data!$A$2:$A$458,"<"&DATE(2023,1,1)) -> 164.6425 | C6: =AVERAGEIFS(Weekly_Data!$C$2:$C$458,Weekly_Data!$A$2:$A$458,">="&DATE(2022,1,1),Weekly_Data!$A$2:$A$458,"<"&DATE(2023,1,1)) -> 177.77808 | D6: =B6/B5-1 -> 0.25300723 | E6: =C6/C5-1 -> 0.3165052 | F6: =C6-B6 -> 13.135577 | G6: =COUNTIFS(Weekly_Data!$A$2:$A$458,">="&DATE(2022,1,1),Weekly_Data!$A$2:$A$458,"<"&DATE(2023,1,1)) -> 52
A7: 2023 | B7: =AVERAGEIFS(Weekly_Data!$B$2:$B$458,Weekly_Data!$A$2:$A$458,">="&DATE(2023,1,1),Weekly_Data!$A$2:$A$458,"<"&DATE(2024,1,1)) -> 147.65019 | C7: =AVERAGEIFS(Weekly_Data!$C$2:$C$458,Weekly_Data!$A$2:$A$458,">="&DATE(2023,1,1),Weekly_Data!$A$2:$A$458,"<"&DATE(2024,1,1)) -> 158.12423 | D7: =B7/B6-1 -> -0.1032073 | E7: =C7/C6-1 -> -0.1105527 | F7: =C7-B7 -> 10.474038 | G7: =COUNTIFS(Weekly_Data!$A$2:$A$458,">="&DATE(2023,1,1),Weekly_Data!$A$2:$A$458,"<"&DATE(2024,1,1)) -> 52
A8: 2024 | B8: =AVERAGEIFS(Weekly_Data!$B$2:$B$458,Weekly_Data!$A$2:$A$458,">="&DATE(2024,1,1),Weekly_Data!$A$2:$A$458,"<"&DATE(2025,1,1)) -> 141.46774 | C8: =AVERAGEIFS(Weekly_Data!$C$2:$C$458,Weekly_Data!$A$2:$A$458,">="&DATE(2024,1,1),Weekly_Data!$A$2:$A$458,"<"&DATE(2025,1,1)) -> 148.36377 | D8: =B8/B7-1 -> -0.041872322 | E8: =C8/C7-1 -> -0.061726512 | F8: =C8-B8 -> 6.8960377 | G8: =COUNTIFS(Weekly_Data!$A$2:$A$458,">="&DATE(2024,1,1),Weekly_Data!$A$2:$A$458,"<"&DATE(2025,1,1)) -> 53
A9: 2025 | B9: =AVERAGEIFS(Weekly_Data!$B$2:$B$458,Weekly_Data!$A$2:$A$458,">="&DATE(2025,1,1),Weekly_Data!$A$2:$A$458,"<"&DATE(2026,1,1)) -> 135.04962 | C9: =AVERAGEIFS(Weekly_Data!$C$2:$C$458,Weekly_Data!$A$2:$A$458,">="&DATE(2025,1,1),Weekly_Data!$A$2:$A$458,"<"&DATE(2026,1,1)) -> 142.69558 | D9: =B9/B8-1 -> -0.045368086 | E9: =C9/C8-1 -> -0.038204722 | F9: =C9-B9 -> 7.6459615 | G9: =COUNTIFS(Weekly_Data!$A$2:$A$458,">="&DATE(2025,1,1),Weekly_Data!$A$2:$A$458,"<"&DATE(2026,1,1)) -> 52
A10: 2026 (YTD) | B10: =AVERAGEIFS(Weekly_Data!$B$2:$B$458,Weekly_Data!$A$2:$A$458,">="&DATE(2026,1,1),Weekly_Data!$A$2:$A$458,"<"&DATE(2027,1,1)) -> 150.97359 | C10: =AVERAGEIFS(Weekly_Data!$C$2:$C$458,Weekly_Data!$A$2:$A$458,">="&DATE(2026,1,1),Weekly_Data!$A$2:$A$458,"<"&DATE(2027,1,1)) -> 170.99615 | D10: =B10/B9-1 -> 0.11791203 | E10: =C10/C9-1 -> 0.19832834 | F10: =C10-B10 -> 20.022564 | G10: =COUNTIFS(Weekly_Data!$A$2:$A$458,">="&DATE(2026,1,1),Weekly_Data!$A$2:$A$458,"<"&DATE(2027,1,1)) -> 39
A12: 2026 is year-to-date (to 28 Sep 2026), so its average and YoY change are not a full-year comparison.

Sheet Forecast_Data
A1: Month | B1: Petrol forecast (p/litre) | C1: Petrol 80% low | D1: Petrol 80% high | E1: Petrol 95% low | F1: Petrol 95% high | G1: Diesel forecast (p/litre) | H1: Diesel 80% low | I1: Diesel 80% high | J1: Diesel 95% low | K1: Diesel 95% high | M1: Diesel data check
A2: 46296 | B2: 171.03549 | C2: 166.21875 | D2: 175.85222 | E2: 163.66893 | F2: 178.40205 | G2: 189.2649 | H2: 183.22299 | I2: 195.30681 | J2: 180.02459 | K2: 198.5052 | M2: =IF(COUNT(G2:G121)<120,"CHECK: diesel columns are not full (120 rows needed)",IF(MAX(G2:G121)=MIN(G2:G121),"CHECK: diesel forecast is the same in every row - re-paste diesel_forecast.csv","OK: diesel forecast varies by month")) -> OK: diesel forecast varies by month
A3: 46327 | B3: 168.82169 | C3: 159.47222 | D3: 178.17117 | E3: 154.5229 | F3: 183.12048 | G3: 183.30851 | H3: 172.03213 | I3: 194.5849 | J3: 166.06277 | K3: 200.55425
A4: 46357 | B4: 168.4305 | C4: 156.17192 | D4: 180.68909 | E4: 149.68261 | F4: 187.1784 | G4: 184.34605 | H4: 169.99072 | I4: 198.70138 | J4: 162.39147 | K4: 206.30063
A5: 46388 | B5: 169.34648 | C5: 155.39104 | D5: 183.30192 | E5: 148.00348 | F5: 190.68948 | G5: 188.86697 | H5: 173.06668 | I5: 204.66727 | J5: 164.70251 | K5: 213.03144
A6: 46419 | B6: 169.41196 | C6: 153.87646 | D6: 184.94745 | E6: 145.65247 | F6: 193.17144 | G6: 188.41302 | H6: 171.21112 | I6: 205.61492 | J6: 162.10498 | K6: 214.72106
A7: 46447 | B7: 169.04239 | C7: 151.87299 | D7: 186.21179 | E7: 142.78406 | F7: 195.30073 | G7: 181.72035 | H7: 162.62992 | I7: 200.81079 | J7: 152.52406 | K7: 210.91665
A8: 46478 | B8: 169.05259 | C8: 150.43443 | D8: 187.67076 | E8: 140.57856 | F8: 197.52662 | G8: 174.39023 | H8: 153.57944 | I8: 195.20103 | J8: 142.56287 | K8: 206.2176
A9: 46508 | B9: 169.19811 | C9: 149.30066 | D9: 189.09557 | E9: 138.76759 | F9: 199.62864 | G9: 176.86175 | H9: 154.79414 | I9: 198.92935 | J9: 143.11226 | K9: 210.61123
A10: 46539 | B10: 169.17983 | C10: 148.0601 | D10: 190.29957 | E10: 136.87999 | F10: 201.47968 | G10: 179.63614 | H10: 156.40777 | I10: 202.86451 | J10: 144.11141 | K10: 215.16086
A11: 46569 | B11: 169.12393 | C11: 146.82787 | D11: 191.41998 | E11: 135.02506 | F11: 203.2228 | G11: 180.63198 | H11: 156.1141 | I11: 205.14987 | J11: 143.13511 | K11: 218.12885
A12: 46600 | B12: 169.13664 | C12: 145.73264 | D12: 192.54065 | E12: 133.34331 | F12: 204.92998 | G12: 176.9775 | H12: 151.20037 | I12: 202.75464 | J12: 137.55478 | K12: 216.40023
A13: 46631 | B13: 169.15757 | C13: 144.70245 | D13: 193.61268 | E13: 131.75669 | F13: 206.55844 | G13: 175.12009 | H13: 148.24942 | I13: 201.99075 | J13: 134.02496 | K13: 216.21521
A14: 46661 | B14: 169.15048 | C14: 143.68358 | D14: 194.61737 | E14: 130.20222 | F14: 208.09873 | G14: 176.01629 | H14: 148.48251 | I14: 203.55006 | J14: 133.90701 | K14: 218.12556
... A121: 49919 | B121: 169.14727 | C121: 91.331679 | D121: 246.96286 | E121: 50.138593 | F121: 288.15595 | G121: 176.28299 | H121: 110.31675 | I121: 242.24924 | J121: 75.396324 | K121: 277.16966
A123: Petrol (B2:F121) and diesel (G2:K121): 120-month forecasts from R (forecast package, auto.arima), fitted to the 105 monthly averages (Jan-18 to Sep-26). Petrol is ARIMA(2,1,2) with no drift; diesel is ARIMA(2,1,2)(0,0,1)[12].
A124: Each fuel has the point forecast plus 80% and 95% ranges, in the same layout. Cell M2 checks the diesel columns are complete and vary by month.
A125: These are statistical ranges from past prices only. They do not include policy, oil-price or EV-demand assumptions (see Scenarios).

Sheet Scenarios
A1: Pump price scenarios vs statistical baseline
A3: Fuel (select Petrol or Diesel) | B3: Petrol | C3: =IF(B3="Diesel",Forecast_Data!M2,"")
A4: Starting pump price (Sep-26 monthly avg, p/litre) | B4: =IF(B3="Petrol",Monthly!B106,Monthly!C106) -> 169.5025
A5: Fuel duty now (p/litre) | B5: =Weekly_Data!D458 -> 52.95
A6: VAT rate | B6: =Weekly_Data!E458/100 -> 0.2
A7: Ex-tax cost now (p/litre: crude + refining, distribution, margin) | B7: =B4/(1+B6)-B5 -> 88.302083
A8: Crude oil cost now (p/litre, from Brent and GBP/USD) | B8: =Assumptions!B5*100/(Assumptions!B7*Assumptions!B6) -> 42.714466
A9: Scenario assumptions (sourced, see Assumptions sheet) | C9: Low | D9: Central | E9: High
A10: DESNZ oil price assumption used | C10: A (low) | D10: B (central) | E10: C (high)
A11: Brent in 2036 (real 2024 $/bbl) | C11: =Assumptions!B32 -> 50 | D11: =Assumptions!C32 -> 79 | E11: =Assumptions!D32 -> 112
A12: Fuel duty step when the 5p cut ends, Jan-27 (p/litre) | C12: 0 | D12: =Assumptions!$B$13 -> 5 | E12: =Assumptions!$B$13 -> 5
A13: Annual fuel duty uprating from Apr-27 (RPI) | C13: 0 | D13: =Assumptions!$B$17 -> 0.0255 | E13: =Assumptions!$B$17 -> 0.0255
A14: Summary (p/litre) | C14: Low | D14: Central | E14: High | F14: Statistical baseline (ARIMA) | G14: ARIMA 80% low | H14: ARIMA 80% high
A15: In 5 years (Sep-31) | C15: =INDEX(C$21:C$140,60) -> 154.19895 | D15: =INDEX(D$21:D$140,60) -> 185.97484 | E15: =INDEX(E$21:E$140,60) -> 207.02532 | F15: =INDEX(F$21:F$140,60) -> 169.14727 | G15: =INDEX(G$21:G$140,60) -> 114.16085 | H15: =INDEX(H$21:H$140,60) -> 224.13369
A16: In 10 years (Sep-36) | C16: =INDEX(C$21:C$140,120) -> 166.53998 | D16: =INDEX(D$21:D$140,120) -> 213.51479 | E16: =INDEX(E$21:E$140,120) -> 237.4825 | F16: =INDEX(F$21:F$140,120) -> 169.14727 | G16: =INDEX(G$21:G$140,120) -> 91.331679 | H16: =INDEX(H$21:H$140,120) -> 246.96286
A17: Change vs today after 10 years | C17: =IF(C16="","",C16-$B$4) -> -2.962516 | D17: =IF(D16="","",D16-$B$4) -> 44.012286 | E17: =IF(E16="","",E16-$B$4) -> 67.980003 | F17: =IF(F16="","",F16-$B$4) -> -0.3552295 | G17: =IF(G16="","",G16-$B$4) -> -78.170821 | H17: =IF(H16="","",H16-$B$4) -> 77.460362
A18: Low: DESNZ low oil case with fuel duty frozen at today's rate (cut made permanent). Central and High: DESNZ central / high oil case with the stated policy (5p cut ends, then RPI uprating from Apr-27).
A19: These are conditional projections, not forecasts. The Budget and OBR forecast on 28 Oct 2026 may change the duty assumptions. Sources and workings: Assumptions and Scenario_Calc sheets.
A20: Month | B20: Years ahead | C20: Low | D20: Central | E20: High | F20: Statistical baseline (ARIMA) | G20: ARIMA 80% low | H20: ARIMA 80% high
A21: =Forecast_Data!A2 -> 46296 | B21: =(ROW()-ROW($A$20))/12 -> 0.083333333 | C21: =(Scenario_Calc!N21+Scenario_Calc!K21)*(1+$B$6) -> 167.65501 | D21: =(Scenario_Calc!O21+Scenario_Calc!L21)*(1+$B$6) -> 168.59838 | E21: =(Scenario_Calc!P21+Scenario_Calc!M21)*(1+$B$6) -> 169.83966 | F21: =IF($B$3="Petrol",Forecast_Data!B2,IF(Forecast_Data!G2="","",Forecast_Data!G2)) -> 171.03549 | G21: =IF($B$3="Petrol",Forecast_Data!C2,IF(Forecast_Data!H2="","",Forecast_Data!H2)) -> 166.21875 | H21: =IF($B$3="Petrol",Forecast_Data!D2,IF(Forecast_Data!I2="","",Forecast_Data!I2)) -> 175.85222
A22: =Forecast_Data!A3 -> 46327 | B22: =(ROW()-ROW($A$20))/12 -> 0.16666667 | C22: =(Scenario_Calc!N22+Scenario_Calc!K22)*(1+$B$6) -> 165.80767 | D22: =(Scenario_Calc!O22+Scenario_Calc!L22)*(1+$B$6) -> 167.69441 | E22: =(Scenario_Calc!P22+Scenario_Calc!M22)*(1+$B$6) -> 170.17697 | F22: =IF($B$3="Petrol",Forecast_Data!B3,IF(Forecast_Data!G3="","",Forecast_Data!G3)) -> 168.82169 | G22: =IF($B$3="Petrol",Forecast_Data!C3,IF(Forecast_Data!H3="","",Forecast_Data!H3)) -> 159.47222 | H22: =IF($B$3="Petrol",Forecast_Data!D3,IF(Forecast_Data!I3="","",Forecast_Data!I3)) -> 178.17117
A23: =Forecast_Data!A4 -> 46357 | B23: =(ROW()-ROW($A$20))/12 -> 0.25 | C23: =(Scenario_Calc!N23+Scenario_Calc!K23)*(1+$B$6) -> 163.96048 | D23: =(Scenario_Calc!O23+Scenario_Calc!L23)*(1+$B$6) -> 166.7906 | E23: =(Scenario_Calc!P23+Scenario_Calc!M23)*(1+$B$6) -> 170.51444 | F23: =IF($B$3="Petrol",Forecast_Data!B4,IF(Forecast_Data!G4="","",Forecast_Data!G4)) -> 168.4305 | G23: =IF($B$3="Petrol",Forecast_Data!C4,IF(Forecast_Data!H4="","",Forecast_Data!H4)) -> 156.17192 | H23: =IF($B$3="Petrol",Forecast_Data!D4,IF(Forecast_Data!I4="","",Forecast_Data!I4)) -> 180.68909
A24: =Forecast_Data!A5 -> 46388 | B24: =(ROW()-ROW($A$20))/12 -> 0.33333333 | C24: =(Scenario_Calc!N24+Scenario_Calc!K24)*(1+$B$6) -> 161.28724 | D24: =(Scenario_Calc!O24+Scenario_Calc!L24)*(1+$B$6) -> 171.74393 | E24: =(Scenario_Calc!P24+Scenario_Calc!M24)*(1+$B$6) -> 178.22639 | F24: =IF($B$3="Petrol",Forecast_Data!B5,IF(Forecast_Data!G5="","",Forecast_Data!G5)) -> 169.34648 | G24: =IF($B$3="Petrol",Forecast_Data!C5,IF(Forecast_Data!H5="","",Forecast_Data!H5)) -> 155.39104 | H24: =IF($B$3="Petrol",Forecast_Data!D5,IF(Forecast_Data!I5="","",Forecast_Data!I5)) -> 183.30192
A25: =Forecast_Data!A6 -> 46419 | B25: =(ROW()-ROW($A$20))/12 -> 0.41666667 | C25: =(Scenario_Calc!N25+Scenario_Calc!K25)*(1+$B$6) -> 159.2338 | D25: =(Scenario_Calc!O25+Scenario_Calc!L25)*(1+$B$6) -> 170.80466 | E25: =(Scenario_Calc!P25+Scenario_Calc!M25)*(1+$B$6) -> 178.90774 | F25: =IF($B$3="Petrol",Forecast_Data!B6,IF(Forecast_Data!G6="","",Forecast_Data!G6)) -> 169.41196 | G25: =IF($B$3="Petrol",Forecast_Data!C6,IF(Forecast_Data!H6="","",Forecast_Data!H6)) -> 153.87646 | H25: =IF($B$3="Petrol",Forecast_Data!D6,IF(Forecast_Data!I6="","",Forecast_Data!I6)) -> 184.94745
A26: =Forecast_Data!A7 -> 46447 | B26: =(ROW()-ROW($A$20))/12 -> 0.5 | C26: =(Scenario_Calc!N26+Scenario_Calc!K26)*(1+$B$6) -> 157.18051 | D26: =(Scenario_Calc!O26+Scenario_Calc!L26)*(1+$B$6) -> 169.86555 | E26: =(Scenario_Calc!P26+Scenario_Calc!M26)*(1+$B$6) -> 179.58924 | F26: =IF($B$3="Petrol",Forecast_Data!B7,IF(Forecast_Data!G7="","",Forecast_Data!G7)) -> 169.04239 | G26: =IF($B$3="Petrol",Forecast_Data!C7,IF(Forecast_Data!H7="","",Forecast_Data!H7)) -> 151.87299 | H26: =IF($B$3="Petrol",Forecast_Data!D7,IF(Forecast_Data!I7="","",Forecast_Data!I7)) -> 186.21179
A27: =Forecast_Data!A8 -> 46478 | B27: =(ROW()-ROW($A$20))/12 -> 0.58333333 | C27: =(Scenario_Calc!N27+Scenario_Calc!K27)*(1+$B$6) -> 155.12737 | D27: =(Scenario_Calc!O27+Scenario_Calc!L27)*(1+$B$6) -> 170.69985 | E27: =(Scenario_Calc!P27+Scenario_Calc!M27)*(1+$B$6) -> 182.04416 | F27: =IF($B$3="Petrol",Forecast_Data!B8,IF(Forecast_Data!G8="","",Forecast_Data!G8)) -> 169.05259 | G27: =IF($B$3="Petrol",Forecast_Data!C8,IF(Forecast_Data!H8="","",Forecast_Data!H8)) -> 150.43443 | H27: =IF($B$3="Petrol",Forecast_Data!D8,IF(Forecast_Data!I8="","",Forecast_Data!I8)) -> 187.67076
A28: =Forecast_Data!A9 -> 46508 | B28: =(ROW()-ROW($A$20))/12 -> 0.66666667 | C28: =(Scenario_Calc!N28+Scenario_Calc!K28)*(1+$B$6) -> 153.07438 | D28: =(Scenario_Calc!O28+Scenario_Calc!L28)*(1+$B$6) -> 169.76103 | E28: =(Scenario_Calc!P28+Scenario_Calc!M28)*(1+$B$6) -> 182.72595 | F28: =IF($B$3="Petrol",Forecast_Data!B9,IF(Forecast_Data!G9="","",Forecast_Data!G9)) -> 169.19811 | G28: =IF($B$3="Petrol",Forecast_Data!C9,IF(Forecast_Data!H9="","",Forecast_Data!H9)) -> 149.30066 | H28: =IF($B$3="Petrol",Forecast_Data!D9,IF(Forecast_Data!I9="","",Forecast_Data!I9)) -> 189.09557
A29: =Forecast_Data!A10 -> 46539 | B29: =(ROW()-ROW($A$20))/12 -> 0.75 | C29: =(Scenario_Calc!N29+Scenario_Calc!K29)*(1+$B$6) -> 151.02154 | D29: =(Scenario_Calc!O29+Scenario_Calc!L29)*(1+$B$6) -> 168.82237 | E29: =(Scenario_Calc!P29+Scenario_Calc!M29)*(1+$B$6) -> 183.4079 | F29: =IF($B$3="Petrol",Forecast_Data!B10,IF(Forecast_Data!G10="","",Forecast_Data!G10)) -> 169.17983 | G29: =IF($B$3="Petrol",Forecast_Data!C10,IF(Forecast_Data!H10="","",Forecast_Data!H10)) -> 148.0601 | H29: =IF($B$3="Petrol",Forecast_Data!D10,IF(Forecast_Data!I10="","",Forecast_Data!I10)) -> 190.29957
A30: =Forecast_Data!A11 -> 46569 | B30: =(ROW()-ROW($A$20))/12 -> 0.83333333 | C30: =(Scenario_Calc!N30+Scenario_Calc!K30)*(1+$B$6) -> 148.96885 | D30: =(Scenario_Calc!O30+Scenario_Calc!L30)*(1+$B$6) -> 167.88385 | E30: =(Scenario_Calc!P30+Scenario_Calc!M30)*(1+$B$6) -> 184.09 | F30: =IF($B$3="Petrol",Forecast_Data!B11,IF(Forecast_Data!G11="","",Forecast_Data!G11)) -> 169.12393 | G30: =IF($B$3="Petrol",Forecast_Data!C11,IF(Forecast_Data!H11="","",Forecast_Data!H11)) -> 146.82787 | H30: =IF($B$3="Petrol",Forecast_Data!D11,IF(Forecast_Data!I11="","",Forecast_Data!I11)) -> 191.41998
A31: =Forecast_Data!A12 -> 46600 | B31: =(ROW()-ROW($A$20))/12 -> 0.91666667 | C31: =(Scenario_Calc!N31+Scenario_Calc!K31)*(1+$B$6) -> 146.91632 | D31: =(Scenario_Calc!O31+Scenario_Calc!L31)*(1+$B$6) -> 166.94549 | E31: =(Scenario_Calc!P31+Scenario_Calc!M31)*(1+$B$6) -> 184.77226 | F31: =IF($B$3="Petrol",Forecast_Data!B12,IF(Forecast_Data!G12="","",Forecast_Data!G12)) -> 169.13664 | G31: =IF($B$3="Petrol",Forecast_Data!C12,IF(Forecast_Data!H12="","",Forecast_Data!H12)) -> 145.73264 | H31: =IF($B$3="Petrol",Forecast_Data!D12,IF(Forecast_Data!I12="","",Forecast_Data!I12)) -> 192.54065
A32: =Forecast_Data!A13 -> 46631 | B32: =(ROW()-ROW($A$20))/12 -> 1 | C32: =(Scenario_Calc!N32+Scenario_Calc!K32)*(1+$B$6) -> 144.86393 | D32: =(Scenario_Calc!O32+Scenario_Calc!L32)*(1+$B$6) -> 166.00728 | E32: =(Scenario_Calc!P32+Scenario_Calc!M32)*(1+$B$6) -> 185.45466 | F32: =IF($B$3="Petrol",Forecast_Data!B13,IF(Forecast_Data!G13="","",Forecast_Data!G13)) -> 169.15757 | G32: =IF($B$3="Petrol",Forecast_Data!C13,IF(Forecast_Data!H13="","",Forecast_Data!H13)) -> 144.70245 | H32: =IF($B$3="Petrol",Forecast_Data!D13,IF(Forecast_Data!I13="","",Forecast_Data!I13)) -> 193.61268
... A140: =Forecast_Data!A121 -> 49919 | B140: =(ROW()-ROW($A$20))/12 -> 10 | C140: =(Scenario_Calc!N140+Scenario_Calc!K140)*(1+$B$6) -> 166.53998 | D140: =(Scenario_Calc!O140+Scenario_Calc!L140)*(1+$B$6) -> 213.51479 | E140: =(Scenario_Calc!P140+Scenario_Calc!M140)*(1+$B$6) -> 237.4825 | F140: =IF($B$3="Petrol",Forecast_Data!B121,IF(Forecast_Data!G121="","",Forecast_Data!G121)) -> 169.14727 | G140: =IF($B$3="Petrol",Forecast_Data!C121,IF(Forecast_Data!H121="","",Forecast_Data!H121)) -> 91.331679 | H140: =IF($B$3="Petrol",Forecast_Data!D121,IF(Forecast_Data!I121="","",Forecast_Data!I121)) -> 246.96286

Sheet Assumptions
A1: Scenario assumptions and sources
A2: Blue = value taken from the cited source (edit if the source is updated). Black = formula. Green = link to another sheet.
A4: Assumption | B4: Value | C4: Unit | D4: Source / note
A5: Brent crude now (Aug-26 monthly average) | B5: 91 | C5: $/bbl, nominal | D5: EIA Short-Term Energy Outlook, 9 Sep 2026: Brent averaged $91/b in Aug 2026 (2026 average forecast $91.01, 2027 $73.74).
A6: GBP/USD (held constant) | B6: 1.34 | C6: $ per £ | D6: Pound Sterling Live: USD/GBP 2026 average 0.7441, i.e. about 1.34 GBP/USD. Held flat over the 10 years (an assumption, not a forecast).
A7: Litres per barrel of oil | B7: 158.987 | C7: litres | D7: Physical constant: 1 oil barrel = 42 US gallons.
A8: UK CPI inflation, 2025 | B8: 0.034 | C8: % a year | D8: OBR Economic and fiscal outlook, March 2026.
A9: UK CPI inflation, 2026 | B9: 0.023 | C9: % a year | D9: OBR March 2026. Note: the OBR finalised this forecast before the Middle East war began, so 2026 inflation may turn out higher.
A10: UK CPI inflation, 2027 onwards | B10: 0.02 | C10: % a year | D10: OBR March 2026 (2.0% from 2027). Used to convert DESNZ real prices to nominal and to grow non-crude costs (refining, distribution, retail margin).
A11: Years for Brent to converge to the DESNZ path | B11: 1 | C11: years | D11: Judgement. EIA Sep-26 STEO has Brent near $90 in H2 2026 and averaging $73.74 in 2027, so a fall over about a year.
A12: Fuel duty before the March 2022 5p cut | B12: 57.95 | C12: p/litre | D12: GOV.UK, Fuel duty rates 2026 to 2027 (rates prior to 23 March 2022).
A13: Fuel duty step when the 5p cut ends | B13: =B12-Scenarios!B5 -> 5 | C13: p/litre | D13: Formula: pre-2022 rate minus current rate (52.95p).
A14: Date the 5p cut ends and the step takes effect | B14: 46388 | C14: date | D14: HMRC/HM Treasury, Amended Fuel Duty rates 2026 to 2027 (22 May 2026): cut extended to 31 Dec 2026. Assumes no further extension and no staging. Budget and OBR forecast due 28 Oct 2026 may change this.
A15: RPI inflation, 2027 to 2029 average | B15: 0.029 | C15: % a year | D15: OBR March 2026, para 2.23. Government policy (Budget Nov 2025): fuel duty uprated by RPI from April 2027.
A16: RPI inflation, long run | B16: 0.024 | C16: % a year | D16: OBR March 2026: RPI (via CPIH) of 2.4% beyond the forecast horizon.
A17: Fuel duty uprating rate used (10-year average) | B17: =(3*B15+7*B16)/10 -> 0.0255 | C17: % a year | D17: Formula: 3 years at the 2027-29 rate, 7 years at the long-run rate.
A18: First April of RPI uprating | B18: 2027 | C18: year | D18: As above.
A20: DESNZ oil price assumptions (Brent, real 2024 prices, $/bbl)
A21: Year | B21: A (Low) | C21: B (Central) | D21: C (High) | E21: CPI price level (2024 = 1)
A22: 2026 | B22: 47 | C22: 66 | D22: 91 | E22: =(1+B8)*(1+B9) -> 1.057782
A23: 2027 | B23: 42 | C23: 64 | D23: 96 | E23: =E22*(1+$B$10) -> 1.0789376
A24: 2028 | B24: 43 | C24: 65 | D24: 98 | E24: =E23*(1+$B$10) -> 1.1005164
A25: 2029 | B25: 44 | C25: 67 | D25: 100 | E25: =E24*(1+$B$10) -> 1.1225267
A26: 2030 | B26: 45 | C26: 69 | D26: 102 | E26: =E25*(1+$B$10) -> 1.1449773
A27: 2031 | B27: 46 | C27: 71 | D27: 103 | E27: =E26*(1+$B$10) -> 1.1678768
A28: 2032 | B28: 47 | C28: 72 | D28: 105 | E28: =E27*(1+$B$10) -> 1.1912343
A29: 2033 | B29: 47 | C29: 74 | D29: 107 | E29: =E28*(1+$B$10) -> 1.215059
A30: 2034 | B30: 48 | C30: 76 | D30: 109 | E30: =E29*(1+$B$10) -> 1.2393602
A31: 2035 | B31: 49 | C31: 77 | D31: 110 | E31: =E30*(1+$B$10) -> 1.2641474
A32: 2036 | B32: 50 | C32: 79 | D32: 112 | E32: =E31*(1+$B$10) -> 1.2894304
A34: Source: DESNZ, Fossil Fuel Price Assumptions 2025 (final report, January 2026), Table 2, GOV.UK. Assumptions A, B and C are the department's low, central and high cases.
A35: DESNZ says these are assumptions for stress-testing, not forecasts or the Government's view of future prices. Short-term values come from forward prices taken in spring 2025, before the 2026 Middle East war.
A36: Oil prices in the Scenarios are nominal: DESNZ real prices multiplied by the CPI price level in column E, then blended from today's Brent over the convergence period above.
A37: Model per month: pump price = (crude cost + non-crude cost + fuel duty) x (1 + VAT). Crude cost = Brent x 100 / (litres per barrel x GBP/USD).
A38: Limitation: non-crude cost (refining, distribution, retail margin) is held constant in real terms from today. Diesel margins are unusually high now, so diesel scenarios may be too high.

Sheet Scenario_Calc
A1: Scenario workings (month by month)
A2: All cells are formulas driven by Assumptions and Scenarios. Nothing to edit here.
A20: Month | B20: Years ahead | C20: CPI price level (2024 = 1) | D20: Brent Low ($/bbl, nominal) | E20: Brent Central ($/bbl, nominal) | F20: Brent High ($/bbl, nominal) | G20: Non-crude cost (p/litre) | H20: Crude cost Low (p/litre) | I20: Crude cost Central (p/litre) | J20: Crude cost High (p/litre) | K20: Fuel duty Low (p/litre) | L20: Fuel duty Central (p/litre) | M20: Fuel duty High (p/litre) | N20: Ex-tax cost Low (p/litre) | O20: Ex-tax cost Central (p/litre) | P20: Ex-tax cost High (p/litre)
A21: =Scenarios!A21 -> 46296 | B21: =Scenarios!B21 -> 0.083333333 | C21: =INDEX(Assumptions!$E$22:$E$32,MATCH(YEAR($A21),Assumptions!$A$22:$A$32,0)) -> 1.057782 | D21: =Assumptions!$B$5+(INDEX(Assumptions!$B$22:$B$32,MATCH(YEAR($A21),Assumptions!$A$22:$A$32,0))*$C21-Assumptions!$B$5)*MIN(1,$B21/Assumptions!$B$11) -> 87.559646 | E21: =Assumptions!$B$5+(INDEX(Assumptions!$C$22:$C$32,MATCH(YEAR($A21),Assumptions!$A$22:$A$32,0))*$C21-Assumptions!$B$5)*MIN(1,$B21/Assumptions!$B$11) -> 89.234468 | F21: =Assumptions!$B$5+(INDEX(Assumptions!$D$22:$D$32,MATCH(YEAR($A21),Assumptions!$A$22:$A$32,0))*$C21-Assumptions!$B$5)*MIN(1,$B21/Assumptions!$B$11) -> 91.43818 | G21: =(Scenarios!$B$7-Scenarios!$B$8)*(1+Assumptions!$B$10)^$B21 -> 45.662909 | H21: =D21*100/(Assumptions!$B$7*Assumptions!$B$6) -> 41.099599 | I21: =E21*100/(Assumptions!$B$7*Assumptions!$B$6) -> 41.885743 | J21: =F21*100/(Assumptions!$B$7*Assumptions!$B$6) -> 42.920143 | K21: =(Scenarios!$B$5+Scenarios!C$12*($A21>=Assumptions!$B$14))*(1+Scenarios!C$13)^MAX(0,YEAR($A21)-Assumptions!$B$18+(MONTH($A21)>=4)) -> 52.95 | L21: =(Scenarios!$B$5+Scenarios!D$12*($A21>=Assumptions!$B$14))*(1+Scenarios!D$13)^MAX(0,YEAR($A21)-Assumptions!$B$18+(MONTH($A21)>=4)) -> 52.95 | M21: =(Scenarios!$B$5+Scenarios!E$12*($A21>=Assumptions!$B$14))*(1+Scenarios!E$13)^MAX(0,YEAR($A21)-Assumptions!$B$18+(MONTH($A21)>=4)) -> 52.95 | N21: =$G21+H21 -> 86.762508 | O21: =$G21+I21 -> 87.548652 | P21: =$G21+J21 -> 88.583052
A22: =Scenarios!A22 -> 46327 | B22: =Scenarios!B22 -> 0.16666667 | C22: =INDEX(Assumptions!$E$22:$E$32,MATCH(YEAR($A22),Assumptions!$A$22:$A$32,0)) -> 1.057782 | D22: =Assumptions!$B$5+(INDEX(Assumptions!$B$22:$B$32,MATCH(YEAR($A22),Assumptions!$A$22:$A$32,0))*$C22-Assumptions!$B$5)*MIN(1,$B22/Assumptions!$B$11) -> 84.119292 | E22: =Assumptions!$B$5+(INDEX(Assumptions!$C$22:$C$32,MATCH(YEAR($A22),Assumptions!$A$22:$A$32,0))*$C22-Assumptions!$B$5)*MIN(1,$B22/Assumptions!$B$11) -> 87.468935 | F22: =Assumptions!$B$5+(INDEX(Assumptions!$D$22:$D$32,MATCH(YEAR($A22),Assumptions!$A$22:$A$32,0))*$C22-Assumptions!$B$5)*MIN(1,$B22/Assumptions!$B$11) -> 91.87636 | G22: =(Scenarios!$B$7-Scenarios!$B$8)*(1+Assumptions!$B$10)^$B22 -> 45.738325 | H22: =D22*100/(Assumptions!$B$7*Assumptions!$B$6) -> 39.484732 | I22: =E22*100/(Assumptions!$B$7*Assumptions!$B$6) -> 41.05702 | J22: =F22*100/(Assumptions!$B$7*Assumptions!$B$6) -> 43.12582 | K22: =(Scenarios!$B$5+Scenarios!C$12*($A22>=Assumptions!$B$14))*(1+Scenarios!C$13)^MAX(0,YEAR($A22)-Assumptions!$B$18+(MONTH($A22)>=4)) -> 52.95 | L22: =(Scenarios!$B$5+Scenarios!D$12*($A22>=Assumptions!$B$14))*(1+Scenarios!D$13)^MAX(0,YEAR($A22)-Assumptions!$B$18+(MONTH($A22)>=4)) -> 52.95 | M22: =(Scenarios!$B$5+Scenarios!E$12*($A22>=Assumptions!$B$14))*(1+Scenarios!E$13)^MAX(0,YEAR($A22)-Assumptions!$B$18+(MONTH($A22)>=4)) -> 52.95 | N22: =$G22+H22 -> 85.223057 | O22: =$G22+I22 -> 86.795345 | P22: =$G22+J22 -> 88.864146
A23: =Scenarios!A23 -> 46357 | B23: =Scenarios!B23 -> 0.25 | C23: =INDEX(Assumptions!$E$22:$E$32,MATCH(YEAR($A23),Assumptions!$A$22:$A$32,0)) -> 1.057782 | D23: =Assumptions!$B$5+(INDEX(Assumptions!$B$22:$B$32,MATCH(YEAR($A23),Assumptions!$A$22:$A$32,0))*$C23-Assumptions!$B$5)*MIN(1,$B23/Assumptions!$B$11) -> 80.678939 | E23: =Assumptions!$B$5+(INDEX(Assumptions!$C$22:$C$32,MATCH(YEAR($A23),Assumptions!$A$22:$A$32,0))*$C23-Assumptions!$B$5)*MIN(1,$B23/Assumptions!$B$11) -> 85.703403 | F23: =Assumptions!$B$5+(INDEX(Assumptions!$D$22:$D$32,MATCH(YEAR($A23),Assumptions!$A$22:$A$32,0))*$C23-Assumptions!$B$5)*MIN(1,$B23/Assumptions!$B$11) -> 92.314541 | G23: =(Scenarios!$B$7-Scenarios!$B$8)*(1+Assumptions!$B$10)^$B23 -> 45.813866 | H23: =D23*100/(Assumptions!$B$7*Assumptions!$B$6) -> 37.869865 | I23: =E23*100/(Assumptions!$B$7*Assumptions!$B$6) -> 40.228298 | J23: =F23*100/(Assumptions!$B$7*Assumptions!$B$6) -> 43.331498 | K23: =(Scenarios!$B$5+Scenarios!C$12*($A23>=Assumptions!$B$14))*(1+Scenarios!C$13)^MAX(0,YEAR($A23)-Assumptions!$B$18+(MONTH($A23)>=4)) -> 52.95 | L23: =(Scenarios!$B$5+Scenarios!D$12*($A23>=Assumptions!$B$14))*(1+Scenarios!D$13)^MAX(0,YEAR($A23)-Assumptions!$B$18+(MONTH($A23)>=4)) -> 52.95 | M23: =(Scenarios!$B$5+Scenarios!E$12*($A23>=Assumptions!$B$14))*(1+Scenarios!E$13)^MAX(0,YEAR($A23)-Assumptions!$B$18+(MONTH($A23)>=4)) -> 52.95 | N23: =$G23+H23 -> 83.683731 | O23: =$G23+I23 -> 86.042163 | P23: =$G23+J23 -> 89.145363
A24: =Scenarios!A24 -> 46388 | B24: =Scenarios!B24 -> 0.33333333 | C24: =INDEX(Assumptions!$E$22:$E$32,MATCH(YEAR($A24),Assumptions!$A$22:$A$32,0)) -> 1.0789376 | D24: =Assumptions!$B$5+(INDEX(Assumptions!$B$22:$B$32,MATCH(YEAR($A24),Assumptions!$A$22:$A$32,0))*$C24-Assumptions!$B$5)*MIN(1,$B24/Assumptions!$B$11) -> 75.771794 | E24: =Assumptions!$B$5+(INDEX(Assumptions!$C$22:$C$32,MATCH(YEAR($A24),Assumptions!$A$22:$A$32,0))*$C24-Assumptions!$B$5)*MIN(1,$B24/Assumptions!$B$11) -> 83.684003 | F24: =Assumptions!$B$5+(INDEX(Assumptions!$D$22:$D$32,MATCH(YEAR($A24),Assumptions!$A$22:$A$32,0))*$C24-Assumptions!$B$5)*MIN(1,$B24/Assumptions!$B$11) -> 95.192671 | G24: =(Scenarios!$B$7-Scenarios!$B$8)*(1+Assumptions!$B$10)^$B24 -> 45.889531 | H24: =D24*100/(Assumptions!$B$7*Assumptions!$B$6) -> 35.566502 | I24: =E24*100/(Assumptions!$B$7*Assumptions!$B$6) -> 39.280412 | J24: =F24*100/(Assumptions!$B$7*Assumptions!$B$6) -> 44.682463 | K24: =(Scenarios!$B$5+Scenarios!C$12*($A24>=Assumptions!$B$14))*(1+Scenarios!C$13)^MAX(0,YEAR($A24)-Assumptions!$B$18+(MONTH($A24)>=4)) -> 52.95 | L24: =(Scenarios!$B$5+Scenarios!D$12*($A24>=Assumptions!$B$14))*(1+Scenarios!D$13)^MAX(0,YEAR($A24)-Assumptions!$B$18+(MONTH($A24)>=4)) -> 57.95 | M24: =(Scenarios!$B$5+Scenarios!E$12*($A24>=Assumptions!$B$14))*(1+Scenarios!E$13)^MAX(0,YEAR($A24)-Assumptions!$B$18+(MONTH($A24)>=4)) -> 57.95 | N24: =$G24+H24 -> 81.456033 | O24: =$G24+I24 -> 85.169943 | P24: =$G24+J24 -> 90.571994
A25: =Scenarios!A25 -> 46419 | B25: =Scenarios!B25 -> 0.41666667 | C25: =INDEX(Assumptions!$E$22:$E$32,MATCH(YEAR($A25),Assumptions!$A$22:$A$32,0)) -> 1.0789376 | D25: =Assumptions!$B$5+(INDEX(Assumptions!$B$22:$B$32,MATCH(YEAR($A25),Assumptions!$A$22:$A$32,0))*$C25-Assumptions!$B$5)*MIN(1,$B25/Assumptions!$B$11) -> 71.964742 | E25: =Assumptions!$B$5+(INDEX(Assumptions!$C$22:$C$32,MATCH(YEAR($A25),Assumptions!$A$22:$A$32,0))*$C25-Assumptions!$B$5)*MIN(1,$B25/Assumptions!$B$11) -> 81.855004 | F25: =Assumptions!$B$5+(INDEX(Assumptions!$D$22:$D$32,MATCH(YEAR($A25),Assumptions!$A$22:$A$32,0))*$C25-Assumptions!$B$5)*MIN(1,$B25/Assumptions!$B$11) -> 96.240839 | G25: =(Scenarios!$B$7-Scenarios!$B$8)*(1+Assumptions!$B$10)^$B25 -> 45.965321 | H25: =D25*100/(Assumptions!$B$7*Assumptions!$B$6) -> 33.779511 | I25: =E25*100/(Assumptions!$B$7*Assumptions!$B$6) -> 38.421898 | J25: =F25*100/(Assumptions!$B$7*Assumptions!$B$6) -> 45.174462 | K25: =(Scenarios!$B$5+Scenarios!C$12*($A25>=Assumptions!$B$14))*(1+Scenarios!C$13)^MAX(0,YEAR($A25)-Assumptions!$B$18+(MONTH($A25)>=4)) -> 52.95 | L25: =(Scenarios!$B$5+Scenarios!D$12*($A25>=Assumptions!$B$14))*(1+Scenarios!D$13)^MAX(0,YEAR($A25)-Assumptions!$B$18+(MONTH($A25)>=4)) -> 57.95 | M25: =(Scenarios!$B$5+Scenarios!E$12*($A25>=Assumptions!$B$14))*(1+Scenarios!E$13)^MAX(0,YEAR($A25)-Assumptions!$B$18+(MONTH($A25)>=4)) -> 57.95 | N25: =$G25+H25 -> 79.744832 | O25: =$G25+I25 -> 84.38722 | P25: =$G25+J25 -> 91.139783
A26: =Scenarios!A26 -> 46447 | B26: =Scenarios!B26 -> 0.5 | C26: =INDEX(Assumptions!$E$22:$E$32,MATCH(YEAR($A26),Assumptions!$A$22:$A$32,0)) -> 1.0789376 | D26: =Assumptions!$B$5+(INDEX(Assumptions!$B$22:$B$32,MATCH(YEAR($A26),Assumptions!$A$22:$A$32,0))*$C26-Assumptions!$B$5)*MIN(1,$B26/Assumptions!$B$11) -> 68.15769 | E26: =Assumptions!$B$5+(INDEX(Assumptions!$C$22:$C$32,MATCH(YEAR($A26),Assumptions!$A$22:$A$32,0))*$C26-Assumptions!$B$5)*MIN(1,$B26/Assumptions!$B$11) -> 80.026004 | F26: =Assumptions!$B$5+(INDEX(Assumptions!$D$22:$D$32,MATCH(YEAR($A26),Assumptions!$A$22:$A$32,0))*$C26-Assumptions!$B$5)*MIN(1,$B26/Assumptions!$B$11) -> 97.289007 | G26: =(Scenarios!$B$7-Scenarios!$B$8)*(1+Assumptions!$B$10)^$B26 -> 46.041237 | H26: =D26*100/(Assumptions!$B$7*Assumptions!$B$6) -> 31.99252 | I26: =E26*100/(Assumptions!$B$7*Assumptions!$B$6) -> 37.563385 | J26: =F26*100/(Assumptions!$B$7*Assumptions!$B$6) -> 45.666461 | K26: =(Scenarios!$B$5+Scenarios!C$12*($A26>=Assumptions!$B$14))*(1+Scenarios!C$13)^MAX(0,YEAR($A26)-Assumptions!$B$18+(MONTH($A26)>=4)) -> 52.95 | L26: =(Scenarios!$B$5+Scenarios!D$12*($A26>=Assumptions!$B$14))*(1+Scenarios!D$13)^MAX(0,YEAR($A26)-Assumptions!$B$18+(MONTH($A26)>=4)) -> 57.95 | M26: =(Scenarios!$B$5+Scenarios!E$12*($A26>=Assumptions!$B$14))*(1+Scenarios!E$13)^MAX(0,YEAR($A26)-Assumptions!$B$18+(MONTH($A26)>=4)) -> 57.95 | N26: =$G26+H26 -> 78.033757 | O26: =$G26+I26 -> 83.604622 | P26: =$G26+J26 -> 91.707698
A27: =Scenarios!A27 -> 46478 | B27: =Scenarios!B27 -> 0.58333333 | C27: =INDEX(Assumptions!$E$22:$E$32,MATCH(YEAR($A27),Assumptions!$A$22:$A$32,0)) -> 1.0789376 | D27: =Assumptions!$B$5+(INDEX(Assumptions!$B$22:$B$32,MATCH(YEAR($A27),Assumptions!$A$22:$A$32,0))*$C27-Assumptions!$B$5)*MIN(1,$B27/Assumptions!$B$11) -> 64.350639 | E27: =Assumptions!$B$5+(INDEX(Assumptions!$C$22:$C$32,MATCH(YEAR($A27),Assumptions!$A$22:$A$32,0))*$C27-Assumptions!$B$5)*MIN(1,$B27/Assumptions!$B$11) -> 78.197005 | F27: =Assumptions!$B$5+(INDEX(Assumptions!$D$22:$D$32,MATCH(YEAR($A27),Assumptions!$A$22:$A$32,0))*$C27-Assumptions!$B$5)*MIN(1,$B27/Assumptions!$B$11) -> 98.337175 | G27: =(Scenarios!$B$7-Scenarios!$B$8)*(1+Assumptions!$B$10)^$B27 -> 46.117278 | H27: =D27*100/(Assumptions!$B$7*Assumptions!$B$6) -> 30.205529 | I27: =E27*100/(Assumptions!$B$7*Assumptions!$B$6) -> 36.704871 | J27: =F27*100/(Assumptions!$B$7*Assumptions!$B$6) -> 46.15846 | K27: =(Scenarios!$B$5+Scenarios!C$12*($A27>=Assumptions!$B$14))*(1+Scenarios!C$13)^MAX(0,YEAR($A27)-Assumptions!$B$18+(MONTH($A27)>=4)) -> 52.95 | L27: =(Scenarios!$B$5+Scenarios!D$12*($A27>=Assumptions!$B$14))*(1+Scenarios!D$13)^MAX(0,YEAR($A27)-Assumptions!$B$18+(MONTH($A27)>=4)) -> 59.427725 | M27: =(Scenarios!$B$5+Scenarios!E$12*($A27>=Assumptions!$B$14))*(1+Scenarios!E$13)^MAX(0,YEAR($A27)-Assumptions!$B$18+(MONTH($A27)>=4)) -> 59.427725 | N27: =$G27+H27 -> 76.322807 | O27: =$G27+I27 -> 82.822149 | P27: =$G27+J27 -> 92.275738
A28: =Scenarios!A28 -> 46508 | B28: =Scenarios!B28 -> 0.66666667 | C28: =INDEX(Assumptions!$E$22:$E$32,MATCH(YEAR($A28),Assumptions!$A$22:$A$32,0)) -> 1.0789376 | D28: =Assumptions!$B$5+(INDEX(Assumptions!$B$22:$B$32,MATCH(YEAR($A28),Assumptions!$A$22:$A$32,0))*$C28-Assumptions!$B$5)*MIN(1,$B28/Assumptions!$B$11) -> 60.543587 | E28: =Assumptions!$B$5+(INDEX(Assumptions!$C$22:$C$32,MATCH(YEAR($A28),Assumptions!$A$22:$A$32,0))*$C28-Assumptions!$B$5)*MIN(1,$B28/Assumptions!$B$11) -> 76.368006 | F28: =Assumptions!$B$5+(INDEX(Assumptions!$D$22:$D$32,MATCH(YEAR($A28),Assumptions!$A$22:$A$32,0))*$C28-Assumptions!$B$5)*MIN(1,$B28/Assumptions!$B$11) -> 99.385342 | G28: =(Scenarios!$B$7-Scenarios!$B$8)*(1+Assumptions!$B$10)^$B28 -> 46.193444 | H28: =D28*100/(Assumptions!$B$7*Assumptions!$B$6) -> 28.418538 | I28: =E28*100/(Assumptions!$B$7*Assumptions!$B$6) -> 35.846358 | J28: =F28*100/(Assumptions!$B$7*Assumptions!$B$6) -> 46.650459 | K28: =(Scenarios!$B$5+Scenarios!C$12*($A28>=Assumptions!$B$14))*(1+Scenarios!C$13)^MAX(0,YEAR($A28)-Assumptions!$B$18+(MONTH($A28)>=4)) -> 52.95 | L28: =(Scenarios!$B$5+Scenarios!D$12*($A28>=Assumptions!$B$14))*(1+Scenarios!D$13)^MAX(0,YEAR($A28)-Assumptions!$B$18+(MONTH($A28)>=4)) -> 59.427725 | M28: =(Scenarios!$B$5+Scenarios!E$12*($A28>=Assumptions!$B$14))*(1+Scenarios!E$13)^MAX(0,YEAR($A28)-Assumptions!$B$18+(MONTH($A28)>=4)) -> 59.427725 | N28: =$G28+H28 -> 74.611982 | O28: =$G28+I28 -> 82.039802 | P28: =$G28+J28 -> 92.843904
A29: =Scenarios!A29 -> 46539 | B29: =Scenarios!B29 -> 0.75 | C29: =INDEX(Assumptions!$E$22:$E$32,MATCH(YEAR($A29),Assumptions!$A$22:$A$32,0)) -> 1.0789376 | D29: =Assumptions!$B$5+(INDEX(Assumptions!$B$22:$B$32,MATCH(YEAR($A29),Assumptions!$A$22:$A$32,0))*$C29-Assumptions!$B$5)*MIN(1,$B29/Assumptions!$B$11) -> 56.736536 | E29: =Assumptions!$B$5+(INDEX(Assumptions!$C$22:$C$32,MATCH(YEAR($A29),Assumptions!$A$22:$A$32,0))*$C29-Assumptions!$B$5)*MIN(1,$B29/Assumptions!$B$11) -> 74.539007 | F29: =Assumptions!$B$5+(INDEX(Assumptions!$D$22:$D$32,MATCH(YEAR($A29),Assumptions!$A$22:$A$32,0))*$C29-Assumptions!$B$5)*MIN(1,$B29/Assumptions!$B$11) -> 100.43351 | G29: =(Scenarios!$B$7-Scenarios!$B$8)*(1+Assumptions!$B$10)^$B29 -> 46.269736 | H29: =D29*100/(Assumptions!$B$7*Assumptions!$B$6) -> 26.631547 | I29: =E29*100/(Assumptions!$B$7*Assumptions!$B$6) -> 34.987845 | J29: =F29*100/(Assumptions!$B$7*Assumptions!$B$6) -> 47.142459 | K29: =(Scenarios!$B$5+Scenarios!C$12*($A29>=Assumptions!$B$14))*(1+Scenarios!C$13)^MAX(0,YEAR($A29)-Assumptions!$B$18+(MONTH($A29)>=4)) -> 52.95 | L29: =(Scenarios!$B$5+Scenarios!D$12*($A29>=Assumptions!$B$14))*(1+Scenarios!D$13)^MAX(0,YEAR($A29)-Assumptions!$B$18+(MONTH($A29)>=4)) -> 59.427725 | M29: =(Scenarios!$B$5+Scenarios!E$12*($A29>=Assumptions!$B$14))*(1+Scenarios!E$13)^MAX(0,YEAR($A29)-Assumptions!$B$18+(MONTH($A29)>=4)) -> 59.427725 | N29: =$G29+H29 -> 72.901284 | O29: =$G29+I29 -> 81.257581 | P29: =$G29+J29 -> 93.412195
A30: =Scenarios!A30 -> 46569 | B30: =Scenarios!B30 -> 0.83333333 | C30: =INDEX(Assumptions!$E$22:$E$32,MATCH(YEAR($A30),Assumptions!$A$22:$A$32,0)) -> 1.0789376 | D30: =Assumptions!$B$5+(INDEX(Assumptions!$B$22:$B$32,MATCH(YEAR($A30),Assumptions!$A$22:$A$32,0))*$C30-Assumptions!$B$5)*MIN(1,$B30/Assumptions!$B$11) -> 52.929484 | E30: =Assumptions!$B$5+(INDEX(Assumptions!$C$22:$C$32,MATCH(YEAR($A30),Assumptions!$A$22:$A$32,0))*$C30-Assumptions!$B$5)*MIN(1,$B30/Assumptions!$B$11) -> 72.710007 | F30: =Assumptions!$B$5+(INDEX(Assumptions!$D$22:$D$32,MATCH(YEAR($A30),Assumptions!$A$22:$A$32,0))*$C30-Assumptions!$B$5)*MIN(1,$B30/Assumptions!$B$11) -> 101.48168 | G30: =(Scenarios!$B$7-Scenarios!$B$8)*(1+Assumptions!$B$10)^$B30 -> 46.346155 | H30: =D30*100/(Assumptions!$B$7*Assumptions!$B$6) -> 24.844556 | I30: =E30*100/(Assumptions!$B$7*Assumptions!$B$6) -> 34.129331 | J30: =F30*100/(Assumptions!$B$7*Assumptions!$B$6) -> 47.634458 | K30: =(Scenarios!$B$5+Scenarios!C$12*($A30>=Assumptions!$B$14))*(1+Scenarios!C$13)^MAX(0,YEAR($A30)-Assumptions!$B$18+(MONTH($A30)>=4)) -> 52.95 | L30: =(Scenarios!$B$5+Scenarios!D$12*($A30>=Assumptions!$B$14))*(1+Scenarios!D$13)^MAX(0,YEAR($A30)-Assumptions!$B$18+(MONTH($A30)>=4)) -> 59.427725 | M30: =(Scenarios!$B$5+Scenarios!E$12*($A30>=Assumptions!$B$14))*(1+Scenarios!E$13)^MAX(0,YEAR($A30)-Assumptions!$B$18+(MONTH($A30)>=4)) -> 59.427725 | N30: =$G30+H30 -> 71.190711 | O30: =$G30+I30 -> 80.475486 | P30: =$G30+J30 -> 93.980612
A31: =Scenarios!A31 -> 46600 | B31: =Scenarios!B31 -> 0.91666667 | C31: =INDEX(Assumptions!$E$22:$E$32,MATCH(YEAR($A31),Assumptions!$A$22:$A$32,0)) -> 1.0789376 | D31: =Assumptions!$B$5+(INDEX(Assumptions!$B$22:$B$32,MATCH(YEAR($A31),Assumptions!$A$22:$A$32,0))*$C31-Assumptions!$B$5)*MIN(1,$B31/Assumptions!$B$11) -> 49.122432 | E31: =Assumptions!$B$5+(INDEX(Assumptions!$C$22:$C$32,MATCH(YEAR($A31),Assumptions!$A$22:$A$32,0))*$C31-Assumptions!$B$5)*MIN(1,$B31/Assumptions!$B$11) -> 70.881008 | F31: =Assumptions!$B$5+(INDEX(Assumptions!$D$22:$D$32,MATCH(YEAR($A31),Assumptions!$A$22:$A$32,0))*$C31-Assumptions!$B$5)*MIN(1,$B31/Assumptions!$B$11) -> 102.52985 | G31: =(Scenarios!$B$7-Scenarios!$B$8)*(1+Assumptions!$B$10)^$B31 -> 46.422699 | H31: =D31*100/(Assumptions!$B$7*Assumptions!$B$6) -> 23.057566 | I31: =E31*100/(Assumptions!$B$7*Assumptions!$B$6) -> 33.270818 | J31: =F31*100/(Assumptions!$B$7*Assumptions!$B$6) -> 48.126457 | K31: =(Scenarios!$B$5+Scenarios!C$12*($A31>=Assumptions!$B$14))*(1+Scenarios!C$13)^MAX(0,YEAR($A31)-Assumptions!$B$18+(MONTH($A31)>=4)) -> 52.95 | L31: =(Scenarios!$B$5+Scenarios!D$12*($A31>=Assumptions!$B$14))*(1+Scenarios!D$13)^MAX(0,YEAR($A31)-Assumptions!$B$18+(MONTH($A31)>=4)) -> 59.427725 | M31: =(Scenarios!$B$5+Scenarios!E$12*($A31>=Assumptions!$B$14))*(1+Scenarios!E$13)^MAX(0,YEAR($A31)-Assumptions!$B$18+(MONTH($A31)>=4)) -> 59.427725 | N31: =$G31+H31 -> 69.480265 | O31: =$G31+I31 -> 79.693517 | P31: =$G31+J31 -> 94.549156
A32: =Scenarios!A32 -> 46631 | B32: =Scenarios!B32 -> 1 | C32: =INDEX(Assumptions!$E$22:$E$32,MATCH(YEAR($A32),Assumptions!$A$22:$A$32,0)) -> 1.0789376 | D32: =Assumptions!$B$5+(INDEX(Assumptions!$B$22:$B$32,MATCH(YEAR($A32),Assumptions!$A$22:$A$32,0))*$C32-Assumptions!$B$5)*MIN(1,$B32/Assumptions!$B$11) -> 45.315381 | E32: =Assumptions!$B$5+(INDEX(Assumptions!$C$22:$C$32,MATCH(YEAR($A32),Assumptions!$A$22:$A$32,0))*$C32-Assumptions!$B$5)*MIN(1,$B32/Assumptions!$B$11) -> 69.052009 | F32: =Assumptions!$B$5+(INDEX(Assumptions!$D$22:$D$32,MATCH(YEAR($A32),Assumptions!$A$22:$A$32,0))*$C32-Assumptions!$B$5)*MIN(1,$B32/Assumptions!$B$11) -> 103.57801 | G32: =(Scenarios!$B$7-Scenarios!$B$8)*(1+Assumptions!$B$10)^$B32 -> 46.49937 | H32: =D32*100/(Assumptions!$B$7*Assumptions!$B$6) -> 21.270575 | I32: =E32*100/(Assumptions!$B$7*Assumptions!$B$6) -> 32.412304 | J32: =F32*100/(Assumptions!$B$7*Assumptions!$B$6) -> 48.618456 | K32: =(Scenarios!$B$5+Scenarios!C$12*($A32>=Assumptions!$B$14))*(1+Scenarios!C$13)^MAX(0,YEAR($A32)-Assumptions!$B$18+(MONTH($A32)>=4)) -> 52.95 | L32: =(Scenarios!$B$5+Scenarios!D$12*($A32>=Assumptions!$B$14))*(1+Scenarios!D$13)^MAX(0,YEAR($A32)-Assumptions!$B$18+(MONTH($A32)>=4)) -> 59.427725 | M32: =(Scenarios!$B$5+Scenarios!E$12*($A32>=Assumptions!$B$14))*(1+Scenarios!E$13)^MAX(0,YEAR($A32)-Assumptions!$B$18+(MONTH($A32)>=4)) -> 59.427725 | N32: =$G32+H32 -> 67.769944 | O32: =$G32+I32 -> 78.911674 | P32: =$G32+J32 -> 95.117826
... A140: =Scenarios!A140 -> 49919 | B140: =Scenarios!B140 -> 10 | C140: =INDEX(Assumptions!$E$22:$E$32,MATCH(YEAR($A140),Assumptions!$A$22:$A$32,0)) -> 1.2894304 | D140: =Assumptions!$B$5+(INDEX(Assumptions!$B$22:$B$32,MATCH(YEAR($A140),Assumptions!$A$22:$A$32,0))*$C140-Assumptions!$B$5)*MIN(1,$B140/Assumptions!$B$11) -> 64.471518 | E140: =Assumptions!$B$5+(INDEX(Assumptions!$C$22:$C$32,MATCH(YEAR($A140),Assumptions!$A$22:$A$32,0))*$C140-Assumptions!$B$5)*MIN(1,$B140/Assumptions!$B$11) -> 101.865 | F140: =Assumptions!$B$5+(INDEX(Assumptions!$D$22:$D$32,MATCH(YEAR($A140),Assumptions!$A$22:$A$32,0))*$C140-Assumptions!$B$5)*MIN(1,$B140/Assumptions!$B$11) -> 144.4162 | G140: =(Scenarios!$B$7-Scenarios!$B$8)*(1+Assumptions!$B$10)^$B140 -> 55.571051 | H140: =D140*100/(Assumptions!$B$7*Assumptions!$B$6) -> 30.262269 | I140: =E140*100/(Assumptions!$B$7*Assumptions!$B$6) -> 47.814384 | J140: =F140*100/(Assumptions!$B$7*Assumptions!$B$6) -> 67.787482 | K140: =(Scenarios!$B$5+Scenarios!C$12*($A140>=Assumptions!$B$14))*(1+Scenarios!C$13)^MAX(0,YEAR($A140)-Assumptions!$B$18+(MONTH($A140)>=4)) -> 52.95 | L140: =(Scenarios!$B$5+Scenarios!D$12*($A140>=Assumptions!$B$14))*(1+Scenarios!D$13)^MAX(0,YEAR($A140)-Assumptions!$B$18+(MONTH($A140)>=4)) -> 74.543553 | M140: =(Scenarios!$B$5+Scenarios!E$12*($A140>=Assumptions!$B$14))*(1+Scenarios!E$13)^MAX(0,YEAR($A140)-Assumptions!$B$18+(MONTH($A140)>=4)) -> 74.543553 | N140: =$G140+H140 -> 85.83332 | O140: =$G140+I140 -> 103.38544 | P140: =$G140+J140 -> 123.35853

Sheet Charts
A1: Charts
